<?xml version="1.0" encoding="utf-8"?>
<!-- =================================================================================== -->
<!-- |    This document was autogenerated by xacro from dot.xacro                      | -->
<!-- |    EDITING THIS FILE BY HAND IS NOT RECOMMENDED                                 | -->
<!-- =================================================================================== -->
<robot name="dot">
  <material name="silver">
    <color rgba="0.700 0.700 0.700 1.000"/>
  </material>
  <transmission name="Rev1_tran">
    <type>transmission_interface/SimpleTransmission</type>
    <joint name="Rev1">
      <hardwareInterface>hardware_interface/EffortJointInterface</hardwareInterface>
    </joint>
    <actuator name="Rev1_actr">
      <hardwareInterface>hardware_interface/EffortJointInterface</hardwareInterface>
      <mechanicalReduction>1</mechanicalReduction>
    </actuator>
  </transmission>
  <transmission name="Rev2_tran">
    <type>transmission_interface/SimpleTransmission</type>
    <joint name="Rev2">
      <hardwareInterface>hardware_interface/EffortJointInterface</hardwareInterface>
    </joint>
    <actuator name="Rev2_actr">
      <hardwareInterface>hardware_interface/EffortJointInterface</hardwareInterface>
      <mechanicalReduction>1</mechanicalReduction>
    </actuator>
  </transmission>
  <transmission name="Rev3_tran">
    <type>transmission_interface/SimpleTransmission</type>
    <joint name="Rev3">
      <hardwareInterface>hardware_interface/EffortJointInterface</hardwareInterface>
    </joint>
    <actuator name="Rev3_actr">
      <hardwareInterface>hardware_interface/EffortJointInterface</hardwareInterface>
      <mechanicalReduction>1</mechanicalReduction>
    </actuator>
  </transmission>
  <transmission name="Rev4_tran">
    <type>transmission_interface/SimpleTransmission</type>
    <joint name="Rev4">
      <hardwareInterface>hardware_interface/EffortJointInterface</hardwareInterface>
    </joint>
    <actuator name="Rev4_actr">
      <hardwareInterface>hardware_interface/EffortJointInterface</hardwareInterface>
      <mechanicalReduction>1</mechanicalReduction>
    </actuator>
  </transmission>
  <transmission name="Rev5_tran">
    <type>transmission_interface/SimpleTransmission</type>
    <joint name="Rev5">
      <hardwareInterface>hardware_interface/EffortJointInterface</hardwareInterface>
    </joint>
    <actuator name="Rev5_actr">
      <hardwareInterface>hardware_interface/EffortJointInterface</hardwareInterface>
      <mechanicalReduction>1</mechanicalReduction>
    </actuator>
  </transmission>
  <transmission name="Rev6_tran">
    <type>transmission_interface/SimpleTransmission</type>
    <joint name="Rev6">
      <hardwareInterface>hardware_interface/EffortJointInterface</hardwareInterface>
    </joint>
    <actuator name="Rev6_actr">
      <hardwareInterface>hardware_interface/EffortJointInterface</hardwareInterface>
      <mechanicalReduction>1</mechanicalReduction>
    </actuator>
  </transmission>
  <transmission name="Rev7_tran">
    <type>transmission_interface/SimpleTransmission</type>
    <joint name="Rev7">
      <hardwareInterface>hardware_interface/EffortJointInterface</hardwareInterface>
    </joint>
    <actuator name="Rev7_actr">
      <hardwareInterface>hardware_interface/EffortJointInterface</hardwareInterface>
      <mechanicalReduction>1</mechanicalReduction>
    </actuator>
  </transmission>
  <transmission name="Rev8_tran">
    <type>transmission_interface/SimpleTransmission</type>
    <joint name="Rev8">
      <hardwareInterface>hardware_interface/EffortJointInterface</hardwareInterface>
    </joint>
    <actuator name="Rev8_actr">
      <hardwareInterface>hardware_interface/EffortJointInterface</hardwareInterface>
      <mechanicalReduction>1</mechanicalReduction>
    </actuator>
  </transmission>
  <transmission name="Rev9_tran">
    <type>transmission_interface/SimpleTransmission</type>
    <joint name="Rev9">
      <hardwareInterface>hardware_interface/EffortJointInterface</hardwareInterface>
    </joint>
    <actuator name="Rev9_actr">
      <hardwareInterface>hardware_interface/EffortJointInterface</hardwareInterface>
      <mechanicalReduction>1</mechanicalReduction>
    </actuator>
  </transmission>
  <transmission name="Rev10_tran">
    <type>transmission_interface/SimpleTransmission</type>
    <joint name="Rev10">
      <hardwareInterface>hardware_interface/EffortJointInterface</hardwareInterface>
    </joint>
    <actuator name="Rev10_actr">
      <hardwareInterface>hardware_interface/EffortJointInterface</hardwareInterface>
      <mechanicalReduction>1</mechanicalReduction>
    </actuator>
  </transmission>
  <transmission name="Rev11_tran">
    <type>transmission_interface/SimpleTransmission</type>
    <joint name="Rev11">
      <hardwareInterface>hardware_interface/EffortJointInterface</hardwareInterface>
    </joint>
    <actuator name="Rev11_actr">
      <hardwareInterface>hardware_interface/EffortJointInterface</hardwareInterface>
      <mechanicalReduction>1</mechanicalReduction>
    </actuator>
  </transmission>
  <transmission name="Rev12_tran">
    <type>transmission_interface/SimpleTransmission</type>
    <joint name="Rev12">
      <hardwareInterface>hardware_interface/EffortJointInterface</hardwareInterface>
    </joint>
    <actuator name="Rev12_actr">
      <hardwareInterface>hardware_interface/EffortJointInterface</hardwareInterface>
      <mechanicalReduction>1</mechanicalReduction>
    </actuator>
  </transmission>
  <gazebo>
    <plugin filename="libgazebo_ros_control.so" name="control"/>
  </gazebo>
  <gazebo reference="base_link">
    <material>Gazebo/Silver</material>
    <mu1>0.2</mu1>
    <mu2>0.2</mu2>
    <selfCollide>true</selfCollide>
    <gravity>true</gravity>
  </gazebo>
  <gazebo reference="rf_hip_link_1">
    <material>Gazebo/Silver</material>
    <mu1>0.2</mu1>
    <mu2>0.2</mu2>
    <selfCollide>true</selfCollide>
  </gazebo>
  <gazebo reference="lf_hip_link_1">
    <material>Gazebo/Silver</material>
    <mu1>0.2</mu1>
    <mu2>0.2</mu2>
    <selfCollide>true</selfCollide>
  </gazebo>
  <gazebo reference="lh_hip_link_1">
    <material>Gazebo/Silver</material>
    <mu1>0.2</mu1>
    <mu2>0.2</mu2>
    <selfCollide>true</selfCollide>
  </gazebo>
  <gazebo reference="rh_hip_link_1">
    <material>Gazebo/Silver</material>
    <mu1>0.2</mu1>
    <mu2>0.2</mu2>
    <selfCollide>true</selfCollide>
  </gazebo>
  <gazebo reference="rf_upper_leg_link_1">
    <material>Gazebo/Silver</material>
    <mu1>0.2</mu1>
    <mu2>0.2</mu2>
    <selfCollide>true</selfCollide>
  </gazebo>
  <gazebo reference="lf_upper_leg_link_1">
    <material>Gazebo/Silver</material>
    <mu1>0.2</mu1>
    <mu2>0.2</mu2>
    <selfCollide>true</selfCollide>
  </gazebo>
  <gazebo reference="lh_upper_leg_link_1">
    <material>Gazebo/Silver</material>
    <mu1>0.2</mu1>
    <mu2>0.2</mu2>
    <selfCollide>true</selfCollide>
  </gazebo>
  <gazebo reference="rh_upper_leg_link_1">
    <material>Gazebo/Silver</material>
    <mu1>0.2</mu1>
    <mu2>0.2</mu2>
    <selfCollide>true</selfCollide>
  </gazebo>
  <gazebo reference="rf_lower_leg_link_1">
    <material>Gazebo/Silver</material>
    <mu1>0.2</mu1>
    <mu2>0.2</mu2>
    <selfCollide>true</selfCollide>
  </gazebo>
  <gazebo reference="lf_lower_leg_link_1">
    <material>Gazebo/Silver</material>
    <mu1>0.2</mu1>
    <mu2>0.2</mu2>
    <selfCollide>true</selfCollide>
  </gazebo>
  <gazebo reference="lh_lower_leg_link_1">
    <material>Gazebo/Silver</material>
    <mu1>0.2</mu1>
    <mu2>0.2</mu2>
    <selfCollide>true</selfCollide>
  </gazebo>
  <gazebo reference="rh_lower_leg_link_1">
    <material>Gazebo/Silver</material>
    <mu1>0.2</mu1>
    <mu2>0.2</mu2>
    <selfCollide>true</selfCollide>
  </gazebo>
  <link name="base_link">
    <inertial>
      <origin rpy="0 0 0" xyz="0.0 0.0 0.0"/>
      <mass value="3.112038732519901"/>
      <inertia ixx="0.001668" ixy="0.0" ixz="0.0" iyy="0.006274" iyz="0.0" izz="0.007065"/>
    </inertial>
    <visual>
      <origin rpy="0 0 0" xyz="0 0 0"/>
      <geometry>
        <mesh filename="package://dot_description/meshes/base_link.stl" scale="0.001 0.001 0.001"/>
      </geometry>
      <material name="silver"/>
    </visual>
    <collision>
      <origin rpy="0 0 0" xyz="0 0 0"/>
      <geometry>
        <mesh filename="package://dot_description/meshes/base_link.stl" scale="0.001 0.001 0.001"/>
      </geometry>
    </collision>
  </link>
  <link name="rf_hip_link_1">
    <inertial>
      <origin rpy="0 0 0" xyz="0.014999999999911737 8.828354713941167e-14 0.0"/>
      <mass value="0.1095410798373143"/>
      <inertia ixx="1.4e-05" ixy="0.0" ixz="0.0" iyy="1.4e-05" iyz="0.0" izz="1.8e-05"/>
    </inertial>
    <visual>
      <origin rpy="0 0 0" xyz="-0.075 0.025 -0.0"/>
      <geometry>
        <mesh filename="package://dot_description/meshes/rf_hip_link_1.stl" scale="0.001 0.001 0.001"/>
      </geometry>
      <material name="silver"/>
    </visual>
    <collision>
      <origin rpy="0 0 0" xyz="-0.075 0.025 -0.0"/>
      <geometry>
        <mesh filename="package://dot_description/meshes/rf_hip_link_1.stl" scale="0.001 0.001 0.001"/>
      </geometry>
    </collision>
  </link>
  <link name="lf_hip_link_1">
    <inertial>
      <origin rpy="0 0 0" xyz="0.014999999999911737 8.828354713941167e-14 0.0"/>
      <mass value="0.1095410798373143"/>
      <inertia ixx="1.4e-05" ixy="0.0" ixz="0.0" iyy="1.4e-05" iyz="0.0" izz="1.8e-05"/>
    </inertial>
    <visual>
      <origin rpy="0 0 0" xyz="-0.075 -0.025 -0.0"/>
      <geometry>
        <mesh filename="package://dot_description/meshes/lf_hip_link_1.stl" scale="0.001 0.001 0.001"/>
      </geometry>
      <material name="silver"/>
    </visual>
    <collision>
      <origin rpy="0 0 0" xyz="-0.075 -0.025 -0.0"/>
      <geometry>
        <mesh filename="package://dot_description/meshes/lf_hip_link_1.stl" scale="0.001 0.001 0.001"/>
      </geometry>
    </collision>
  </link>
  <link name="lh_hip_link_1">
    <inertial>
      <origin rpy="0 0 0" xyz="-0.01500000000008829 8.828354713941167e-14 0.0"/>
      <mass value="0.1095410798373143"/>
      <inertia ixx="1.4e-05" ixy="-0.0" ixz="-0.0" iyy="1.4e-05" iyz="0.0" izz="1.8e-05"/>
    </inertial>
    <visual>
      <origin rpy="0 0 0" xyz="0.075 -0.025 -0.0"/>
      <geometry>
        <mesh filename="package://dot_description/meshes/lh_hip_link_1.stl" scale="0.001 0.001 0.001"/>
      </geometry>
      <material name="silver"/>
    </visual>
    <collision>
      <origin rpy="0 0 0" xyz="0.075 -0.025 -0.0"/>
      <geometry>
        <mesh filename="package://dot_description/meshes/lh_hip_link_1.stl" scale="0.001 0.001 0.001"/>
      </geometry>
    </collision>
  </link>
  <link name="rh_hip_link_1">
    <inertial>
      <origin rpy="0 0 0" xyz="-0.01500000000008829 8.828354713941167e-14 0.0"/>
      <mass value="0.1095410798373143"/>
      <inertia ixx="1.4e-05" ixy="0.0" ixz="-0.0" iyy="1.4e-05" iyz="0.0" izz="1.8e-05"/>
    </inertial>
    <visual>
      <origin rpy="0 0 0" xyz="0.075 0.025 -0.0"/>
      <geometry>
        <mesh filename="package://dot_description/meshes/rh_hip_link_1.stl" scale="0.001 0.001 0.001"/>
      </geometry>
      <material name="silver"/>
    </visual>
    <collision>
      <origin rpy="0 0 0" xyz="0.075 0.025 -0.0"/>
      <geometry>
        <mesh filename="package://dot_description/meshes/rh_hip_link_1.stl" scale="0.001 0.001 0.001"/>
      </geometry>
    </collision>
  </link>
  <link name="rf_upper_leg_link_1">
    <inertial>
      <origin rpy="0 0 0" xyz="-5.69266855876549e-14 -0.0049999999999999906 -0.030000000000000006"/>
      <mass value="0.11326924883465952"/>
      <inertia ixx="5.7e-05" ixy="0.0" ixz="-0.0" iyy="6e-05" iyz="0.0" izz="5e-06"/>
    </inertial>
    <visual>
      <origin rpy="0 0 0" xyz="-0.09 0.04 -0.0"/>
      <geometry>
        <mesh filename="package://dot_description/meshes/rf_upper_leg_link_1.stl" scale="0.001 0.001 0.001"/>
      </geometry>
      <material name="silver"/>
    </visual>
    <collision>
      <origin rpy="0 0 0" xyz="-0.09 0.04 -0.0"/>
      <geometry>
        <mesh filename="package://dot_description/meshes/rf_upper_leg_link_1.stl" scale="0.001 0.001 0.001"/>
      </geometry>
    </collision>
  </link>
  <link name="lf_upper_leg_link_1">
    <inertial>
      <origin rpy="0 0 0" xyz="-5.69266855876549e-14 0.0049999999999999975 -0.030000000000000006"/>
      <mass value="0.11326924883465952"/>
      <inertia ixx="5.7e-05" ixy="-0.0" ixz="-0.0" iyy="6e-05" iyz="-0.0" izz="5e-06"/>
    </inertial>
    <visual>
      <origin rpy="0 0 0" xyz="-0.09 -0.04 -0.0"/>
      <geometry>
        <mesh filename="package://dot_description/meshes/lf_upper_leg_link_1.stl" scale="0.001 0.001 0.001"/>
      </geometry>
      <material name="silver"/>
    </visual>
    <collision>
      <origin rpy="0 0 0" xyz="-0.09 -0.04 -0.0"/>
      <geometry>
        <mesh filename="package://dot_description/meshes/lf_upper_leg_link_1.stl" scale="0.001 0.001 0.001"/>
      </geometry>
    </collision>
  </link>
  <link name="lh_upper_leg_link_1">
    <inertial>
      <origin rpy="0 0 0" xyz="5.69266855876549e-14 0.0049999999999999975 -0.030000000000000006"/>
      <mass value="0.11326924883465952"/>
      <inertia ixx="5.7e-05" ixy="0.0" ixz="0.0" iyy="6e-05" iyz="-0.0" izz="5e-06"/>
    </inertial>
    <visual>
      <origin rpy="0 0 0" xyz="0.09 -0.04 -0.0"/>
      <geometry>
        <mesh filename="package://dot_description/meshes/lh_upper_leg_link_1.stl" scale="0.001 0.001 0.001"/>
      </geometry>
      <material name="silver"/>
    </visual>
    <collision>
      <origin rpy="0 0 0" xyz="0.09 -0.04 -0.0"/>
      <geometry>
        <mesh filename="package://dot_description/meshes/lh_upper_leg_link_1.stl" scale="0.001 0.001 0.001"/>
      </geometry>
    </collision>
  </link>
  <link name="rh_upper_leg_link_1">
    <inertial>
      <origin rpy="0 0 0" xyz="5.69266855876549e-14 -0.0049999999999999906 -0.030000000000000006"/>
      <mass value="0.11326924883465952"/>
      <inertia ixx="5.7e-05" ixy="-0.0" ixz="0.0" iyy="6e-05" iyz="0.0" izz="5e-06"/>
    </inertial>
    <visual>
      <origin rpy="0 0 0" xyz="0.09 0.04 -0.0"/>
      <geometry>
        <mesh filename="package://dot_description/meshes/rh_upper_leg_link_1.stl" scale="0.001 0.001 0.001"/>
      </geometry>
      <material name="silver"/>
    </visual>
    <collision>
      <origin rpy="0 0 0" xyz="0.09 0.04 -0.0"/>
      <geometry>
        <mesh filename="package://dot_description/meshes/rh_upper_leg_link_1.stl" scale="0.001 0.001 0.001"/>
      </geometry>
    </collision>
  </link>
  <link name="rf_lower_leg_link_1">
    <inertial>
      <origin rpy="0 0 0" xyz="-2.6978419498391304e-14 -0.0049999999999999975 -0.03154864025723239"/>
      <mass value="0.11943462441732976"/>
      <inertia ixx="6.2e-05" ixy="-0.0" ixz="0.0" iyy="6.5e-05" iyz="0.0" izz="5e-06"/>
    </inertial>
    <visual>
      <origin rpy="0 0 0" xyz="-0.09 0.05 0.06"/>
      <geometry>
        <mesh filename="package://dot_description/meshes/rf_lower_leg_link_1.stl" scale="0.001 0.001 0.001"/>
      </geometry>
      <material name="silver"/>
    </visual>
    <collision>
      <origin rpy="0 0 0" xyz="-0.09 0.05 0.06"/>
      <geometry>
        <mesh filename="package://dot_description/meshes/rf_lower_leg_link_1.stl" scale="0.001 0.001 0.001"/>
      </geometry>
    </collision>
  </link>
  <link name="lf_lower_leg_link_1">
    <inertial>
      <origin rpy="0 0 0" xyz="-2.6978419498391304e-14 0.0050000000000000044 -0.03154864025723239"/>
      <mass value="0.11943462441732976"/>
      <inertia ixx="6.2e-05" ixy="0.0" ixz="0.0" iyy="6.5e-05" iyz="-0.0" izz="5e-06"/>
    </inertial>
    <visual>
      <origin rpy="0 0 0" xyz="-0.09 -0.05 0.06"/>
      <geometry>
        <mesh filename="package://dot_description/meshes/lf_lower_leg_link_1.stl" scale="0.001 0.001 0.001"/>
      </geometry>
      <material name="silver"/>
    </visual>
    <collision>
      <origin rpy="0 0 0" xyz="-0.09 -0.05 0.06"/>
      <geometry>
        <mesh filename="package://dot_description/meshes/lf_lower_leg_link_1.stl" scale="0.001 0.001 0.001"/>
      </geometry>
    </collision>
  </link>
  <link name="lh_lower_leg_link_1">
    <inertial>
      <origin rpy="0 0 0" xyz="2.6978419498391304e-14 0.0050000000000000044 -0.03154864025723239"/>
      <mass value="0.11943462441732976"/>
      <inertia ixx="6.2e-05" ixy="-0.0" ixz="-0.0" iyy="6.5e-05" iyz="-0.0" izz="5e-06"/>
    </inertial>
    <visual>
      <origin rpy="0 0 0" xyz="0.09 -0.05 0.06"/>
      <geometry>
        <mesh filename="package://dot_description/meshes/lh_lower_leg_link_1.stl" scale="0.001 0.001 0.001"/>
      </geometry>
      <material name="silver"/>
    </visual>
    <collision>
      <origin rpy="0 0 0" xyz="0.09 -0.05 0.06"/>
      <geometry>
        <mesh filename="package://dot_description/meshes/lh_lower_leg_link_1.stl" scale="0.001 0.001 0.001"/>
      </geometry>
    </collision>
  </link>
  <link name="rh_lower_leg_link_1">
    <inertial>
      <origin rpy="0 0 0" xyz="2.6978419498391304e-14 -0.0049999999999999975 -0.03154864025723239"/>
      <mass value="0.11943462441732976"/>
      <inertia ixx="6.2e-05" ixy="0.0" ixz="-0.0" iyy="6.5e-05" iyz="0.0" izz="5e-06"/>
    </inertial>
    <visual>
      <origin rpy="0 0 0" xyz="0.09 0.05 0.06"/>
      <geometry>
        <mesh filename="package://dot_description/meshes/rh_lower_leg_link_1.stl" scale="0.001 0.001 0.001"/>
      </geometry>
      <material name="silver"/>
    </visual>
    <collision>
      <origin rpy="0 0 0" xyz="0.09 0.05 0.06"/>
      <geometry>
        <mesh filename="package://dot_description/meshes/rh_lower_leg_link_1.stl" scale="0.001 0.001 0.001"/>
      </geometry>
    </collision>
  </link>
  <link name="rf_foot_link"/>
  <link name="lf_foot_link"/>
  <link name="rh_foot_link"/>
  <link name="lh_foot_link"/>
  <joint name="Rev1" type="continuous">
    <origin rpy="0 0 0" xyz="0.075 -0.025 0.0"/>
    <parent link="base_link"/>
    <child link="rf_hip_link_1"/>
    <axis xyz="1.0 0.0 0.0"/>
  </joint>
  <joint name="Rev2" type="continuous">
    <origin rpy="0 0 0" xyz="0.075 0.025 0.0"/>
    <parent link="base_link"/>
    <child link="lf_hip_link_1"/>
    <axis xyz="1.0 0.0 0.0"/>
  </joint>
  <joint name="Rev3" type="continuous">
    <origin rpy="0 0 0" xyz="-0.075 0.025 0.0"/>
    <parent link="base_link"/>
    <child link="lh_hip_link_1"/>
    <axis xyz="1.0 0.0 0.0"/>
  </joint>
  <joint name="Rev4" type="continuous">
    <origin rpy="0 0 0" xyz="-0.075 -0.025 0.0"/>
    <parent link="base_link"/>
    <child link="rh_hip_link_1"/>
    <axis xyz="1.0 0.0 0.0"/>
  </joint>
  <joint name="Rev5" type="continuous">
    <origin rpy="0 0 0" xyz="0.015 -0.015 0.0"/>
    <parent link="rf_hip_link_1"/>
    <child link="rf_upper_leg_link_1"/>
    <axis xyz="0.0 1.0 0.0"/>
  </joint>
  <joint name="Rev6" type="continuous">
    <origin rpy="0 0 0" xyz="0.015 0.015 0.0"/>
    <parent link="lf_hip_link_1"/>
    <child link="lf_upper_leg_link_1"/>
    <axis xyz="0.0 1.0 0.0"/>
  </joint>
  <joint name="Rev7" type="continuous">
    <origin rpy="0 0 0" xyz="-0.015 0.015 0.0"/>
    <parent link="lh_hip_link_1"/>
    <child link="lh_upper_leg_link_1"/>
    <axis xyz="0.0 1.0 0.0"/>
  </joint>
  <joint name="Rev8" type="continuous">
    <origin rpy="0 0 0" xyz="-0.015 -0.015 0.0"/>
    <parent link="rh_hip_link_1"/>
    <child link="rh_upper_leg_link_1"/>
    <axis xyz="0.0 1.0 0.0"/>
  </joint>
  <joint name="Rev9" type="continuous">
    <origin rpy="0 0 0" xyz="0.0 -0.01 -0.06"/>
    <parent link="rf_upper_leg_link_1"/>
    <child link="rf_lower_leg_link_1"/>
    <axis xyz="0.0 1.0 0.0"/>
  </joint>
  <joint name="Rev10" type="continuous">
    <origin rpy="0 0 0" xyz="0.0 0.01 -0.06"/>
    <parent link="lf_upper_leg_link_1"/>
    <child link="lf_lower_leg_link_1"/>
    <axis xyz="0.0 1.0 0.0"/>
  </joint>
  <joint name="Rev11" type="continuous">
    <origin rpy="0 0 0" xyz="0.0 0.01 -0.06"/>
    <parent link="lh_upper_leg_link_1"/>
    <child link="lh_lower_leg_link_1"/>
    <axis xyz="0.0 1.0 0.0"/>
  </joint>
  <joint name="Rev12" type="continuous">
    <origin rpy="0 0 0" xyz="0.0 -0.01 -0.06"/>
    <parent link="rh_upper_leg_link_1"/>
    <child link="rh_lower_leg_link_1"/>
    <axis xyz="0.0 1.0 0.0"/>
  </joint>
  <joint name="RFfoot" type="fixed">
    <origin rpy="0 0 0" xyz="0.0 0.0 -0.07"/>
    <parent link="rf_lower_leg_link_1"/>
    <child link="rf_foot_link"/>
  </joint>
  <joint name="LFfoot" type="fixed">
    <origin rpy="0 0 0" xyz="0.0 0.0 -0.07"/>
    <parent link="lf_lower_leg_link_1"/>
    <child link="lf_foot_link"/>
  </joint>
  <joint name="LHfoot" type="fixed">
    <origin rpy="0 0 0" xyz="0.0 0.0 -0.07"/>
    <parent link="lh_lower_leg_link_1"/>
    <child link="lh_foot_link"/>
  </joint>
  <joint name="RHfoot" type="fixed">
    <origin rpy="0 0 0" xyz="0.0 0.0 -0.07"/>
    <parent link="rh_lower_leg_link_1"/>
    <child link="rh_foot_link"/>
  </joint>
</robot>

